[2019-08-06 22:46:00,206][Thread-33:23088][task_id:django.request][log.py:228][ERROR][Internal Server Error: /log/]
Traceback (most recent call last):
  File "D:\Program Files\Python36\lib\site-packages\django\db\backends\utils.py", line 82, in _execute
    return self.cursor.execute(sql)
  File "D:\Program Files\Python36\lib\site-packages\django\db\backends\mysql\base.py", line 71, in execute
    return self.cursor.execute(query, args)
  File "D:\Program Files\Python36\lib\site-packages\MySQLdb\cursors.py", line 206, in execute
    res = self._query(query)
  File "D:\Program Files\Python36\lib\site-packages\MySQLdb\cursors.py", line 312, in _query
    db.query(q)
  File "D:\Program Files\Python36\lib\site-packages\MySQLdb\connections.py", line 224, in query
    _mysql.connection.query(self, query)
MySQLdb._exceptions.OperationalError: (1054, "Unknown column 'rev.employe_id' in 'on clause'")

The above exception was the direct cause of the following exception:

Traceback (most recent call last):
  File "D:\Program Files\Python36\lib\site-packages\django\core\handlers\exception.py", line 34, in inner
    response = get_response(request)
  File "D:\Program Files\Python36\lib\site-packages\django\core\handlers\base.py", line 115, in _get_response
    response = self.process_exception_by_middleware(e, request)
  File "D:\Program Files\Python36\lib\site-packages\django\core\handlers\base.py", line 113, in _get_response
    response = wrapped_callback(request, *callback_args, **callback_kwargs)
  File "D:\github_workspace\kangni\log\views.py", line 12, in index
    context = {"bar": bar(), "geo": geo(), "pie_base": pie_base(), "gauge_base": gauge_base()}
  File "D:\github_workspace\kangni\log\views.py", line 78, in bar
    GROUP BY employe_id,event_type_id;""")
  File "D:\Program Files\Python36\lib\site-packages\django\db\backends\utils.py", line 99, in execute
    return super().execute(sql, params)
  File "D:\Program Files\Python36\lib\site-packages\django\db\backends\utils.py", line 67, in execute
    return self._execute_with_wrappers(sql, params, many=False, executor=self._execute)
  File "D:\Program Files\Python36\lib\site-packages\django\db\backends\utils.py", line 76, in _execute_with_wrappers
    return executor(sql, params, many, context)
  File "D:\Program Files\Python36\lib\site-packages\django\db\backends\utils.py", line 84, in _execute
    return self.cursor.execute(sql, params)
  File "D:\Program Files\Python36\lib\site-packages\django\db\utils.py", line 89, in __exit__
    raise dj_exc_value.with_traceback(traceback) from exc_value
  File "D:\Program Files\Python36\lib\site-packages\django\db\backends\utils.py", line 82, in _execute
    return self.cursor.execute(sql)
  File "D:\Program Files\Python36\lib\site-packages\django\db\backends\mysql\base.py", line 71, in execute
    return self.cursor.execute(query, args)
  File "D:\Program Files\Python36\lib\site-packages\MySQLdb\cursors.py", line 206, in execute
    res = self._query(query)
  File "D:\Program Files\Python36\lib\site-packages\MySQLdb\cursors.py", line 312, in _query
    db.query(q)
  File "D:\Program Files\Python36\lib\site-packages\MySQLdb\connections.py", line 224, in query
    _mysql.connection.query(self, query)
django.db.utils.OperationalError: (1054, "Unknown column 'rev.employe_id' in 'on clause'")
[2019-08-06 23:44:38,544][Thread-7:9456][task_id:django.request][log.py:228][ERROR][Internal Server Error: /log/]
Traceback (most recent call last):
  File "D:\pyWorkSpace\kangni\venv\lib\site-packages\django\db\backends\utils.py", line 82, in _execute
    return self.cursor.execute(sql)
  File "D:\pyWorkSpace\kangni\venv\lib\site-packages\django\db\backends\mysql\base.py", line 71, in execute
    return self.cursor.execute(query, args)
  File "D:\pyWorkSpace\kangni\venv\lib\site-packages\MySQLdb\cursors.py", line 206, in execute
    res = self._query(query)
  File "D:\pyWorkSpace\kangni\venv\lib\site-packages\MySQLdb\cursors.py", line 312, in _query
    db.query(q)
  File "D:\pyWorkSpace\kangni\venv\lib\site-packages\MySQLdb\connections.py", line 224, in query
    _mysql.connection.query(self, query)
MySQLdb._exceptions.OperationalError: (1054, "Unknown column 'rev.employe_id' in 'on clause'")

The above exception was the direct cause of the following exception:

Traceback (most recent call last):
  File "D:\pyWorkSpace\kangni\venv\lib\site-packages\django\core\handlers\exception.py", line 34, in inner
    response = get_response(request)
  File "D:\pyWorkSpace\kangni\venv\lib\site-packages\django\core\handlers\base.py", line 115, in _get_response
    response = self.process_exception_by_middleware(e, request)
  File "D:\pyWorkSpace\kangni\venv\lib\site-packages\django\core\handlers\base.py", line 113, in _get_response
    response = wrapped_callback(request, *callback_args, **callback_kwargs)
  File "D:\pyWorkSpace\kangni\log\views.py", line 12, in index
    context = {"bar": bar(), "geo": geo(), "pie_base": pie_base(), "gauge_base": gauge_base()}
  File "D:\pyWorkSpace\kangni\log\views.py", line 78, in bar
    GROUP BY employe_id,event_type_id;""")
  File "D:\pyWorkSpace\kangni\venv\lib\site-packages\django\db\backends\utils.py", line 99, in execute
    return super().execute(sql, params)
  File "D:\pyWorkSpace\kangni\venv\lib\site-packages\django\db\backends\utils.py", line 67, in execute
    return self._execute_with_wrappers(sql, params, many=False, executor=self._execute)
  File "D:\pyWorkSpace\kangni\venv\lib\site-packages\django\db\backends\utils.py", line 76, in _execute_with_wrappers
    return executor(sql, params, many, context)
  File "D:\pyWorkSpace\kangni\venv\lib\site-packages\django\db\backends\utils.py", line 84, in _execute
    return self.cursor.execute(sql, params)
  File "D:\pyWorkSpace\kangni\venv\lib\site-packages\django\db\utils.py", line 89, in __exit__
    raise dj_exc_value.with_traceback(traceback) from exc_value
  File "D:\pyWorkSpace\kangni\venv\lib\site-packages\django\db\backends\utils.py", line 82, in _execute
    return self.cursor.execute(sql)
  File "D:\pyWorkSpace\kangni\venv\lib\site-packages\django\db\backends\mysql\base.py", line 71, in execute
    return self.cursor.execute(query, args)
  File "D:\pyWorkSpace\kangni\venv\lib\site-packages\MySQLdb\cursors.py", line 206, in execute
    res = self._query(query)
  File "D:\pyWorkSpace\kangni\venv\lib\site-packages\MySQLdb\cursors.py", line 312, in _query
    db.query(q)
  File "D:\pyWorkSpace\kangni\venv\lib\site-packages\MySQLdb\connections.py", line 224, in query
    _mysql.connection.query(self, query)
django.db.utils.OperationalError: (1054, "Unknown column 'rev.employe_id' in 'on clause'")
[2019-08-07 00:07:34,603][Thread-7:2744][task_id:resource.views][views.py:57][ERROR][摄像头不存在！]
[2019-08-07 00:24:03,933][Thread-6:8852][task_id:django.request][log.py:228][ERROR][Internal Server Error: /log/]
Traceback (most recent call last):
  File "D:\pyWorkSpace\kangni\venv\lib\site-packages\django\core\handlers\exception.py", line 34, in inner
    response = get_response(request)
  File "D:\pyWorkSpace\kangni\venv\lib\site-packages\django\core\handlers\base.py", line 115, in _get_response
    response = self.process_exception_by_middleware(e, request)
  File "D:\pyWorkSpace\kangni\venv\lib\site-packages\django\core\handlers\base.py", line 113, in _get_response
    response = wrapped_callback(request, *callback_args, **callback_kwargs)
  File "D:\pyWorkSpace\kangni\log\views.py", line 13, in index
    context = {"bar": bar(), "geo": geo(), "pie_base": pie_base(), "gauge_base": gauge_base()}
  File "D:\pyWorkSpace\kangni\log\views.py", line 117, in pie_base
    .add("", ['人脸识别','未系安全带','未戴安全帽','跨越围栏'], [4,9,5,1])
TypeError: add() takes 3 positional arguments but 4 were given
[2019-08-07 00:46:51,592][Thread-6:8888][task_id:django.request][log.py:228][ERROR][Internal Server Error: /log/]
Traceback (most recent call last):
  File "D:\pyWorkSpace\kangni\venv\lib\site-packages\django\core\handlers\exception.py", line 34, in inner
    response = get_response(request)
  File "D:\pyWorkSpace\kangni\venv\lib\site-packages\django\core\handlers\base.py", line 115, in _get_response
    response = self.process_exception_by_middleware(e, request)
  File "D:\pyWorkSpace\kangni\venv\lib\site-packages\django\core\handlers\base.py", line 113, in _get_response
    response = wrapped_callback(request, *callback_args, **callback_kwargs)
  File "D:\pyWorkSpace\kangni\log\views.py", line 13, in index
    context = {"bar": bar(), "line": line(), "pie_base": pie_base(), "gauge_base": gauge_base()}
  File "D:\pyWorkSpace\kangni\log\views.py", line 103, in bar
    tmp_list[index] = row[2]
IndexError: tuple index out of range
[2019-08-07 11:27:24,837][Thread-6:3180][task_id:django.request][log.py:228][ERROR][Internal Server Error: /log/]
Traceback (most recent call last):
  File "D:\pyWorkSpace\kangni\venv\lib\site-packages\django\core\handlers\exception.py", line 34, in inner
    response = get_response(request)
  File "D:\pyWorkSpace\kangni\venv\lib\site-packages\django\core\handlers\base.py", line 115, in _get_response
    response = self.process_exception_by_middleware(e, request)
  File "D:\pyWorkSpace\kangni\venv\lib\site-packages\django\core\handlers\base.py", line 113, in _get_response
    response = wrapped_callback(request, *callback_args, **callback_kwargs)
  File "D:\pyWorkSpace\kangni\log\views.py", line 13, in index
    context = {"bar": bar(), "line": line(), "pie_base": pie_base(), "timeline_bar": timeline_bar()}
  File "D:\pyWorkSpace\kangni\log\views.py", line 211, in timeline_bar
    num = row[3]
IndexError: tuple index out of range
[2019-08-07 11:28:01,977][Thread-6:3180][task_id:django.request][log.py:228][ERROR][Internal Server Error: /log/]
Traceback (most recent call last):
  File "D:\pyWorkSpace\kangni\venv\lib\site-packages\django\core\handlers\exception.py", line 34, in inner
    response = get_response(request)
  File "D:\pyWorkSpace\kangni\venv\lib\site-packages\django\core\handlers\base.py", line 115, in _get_response
    response = self.process_exception_by_middleware(e, request)
  File "D:\pyWorkSpace\kangni\venv\lib\site-packages\django\core\handlers\base.py", line 113, in _get_response
    response = wrapped_callback(request, *callback_args, **callback_kwargs)
  File "D:\pyWorkSpace\kangni\log\views.py", line 13, in index
    context = {"bar": bar(), "line": line(), "pie_base": pie_base(), "timeline_bar": timeline_bar()}
  File "D:\pyWorkSpace\kangni\log\views.py", line 211, in timeline_bar
    num = row[3]
IndexError: tuple index out of range
[2019-08-07 12:53:31,380][Thread-13:18708][task_id:resource.views][views.py:57][ERROR][摄像头不存在！]
[2019-08-09 19:29:59,849][Thread-9:6076][task_id:django.request][log.py:228][ERROR][Internal Server Error: /resource/event/]
Traceback (most recent call last):
  File "D:\pyWorkSpace\kangni\venv\lib\site-packages\django\db\models\options.py", line 565, in get_field
    return self.fields_map[field_name]
KeyError: 'district'

During handling of the above exception, another exception occurred:

Traceback (most recent call last):
  File "D:\pyWorkSpace\kangni\venv\lib\site-packages\django\contrib\admin\utils.py", line 262, in lookup_field
    f = _get_non_gfk_field(opts, name)
  File "D:\pyWorkSpace\kangni\venv\lib\site-packages\django\contrib\admin\utils.py", line 293, in _get_non_gfk_field
    field = opts.get_field(name)
  File "D:\pyWorkSpace\kangni\venv\lib\site-packages\django\db\models\options.py", line 567, in get_field
    raise FieldDoesNotExist("%s has no field named '%s'" % (self.object_name, field_name))
django.core.exceptions.FieldDoesNotExist: Event has no field named 'district'

During handling of the above exception, another exception occurred:

Traceback (most recent call last):
  File "D:\pyWorkSpace\kangni\venv\lib\site-packages\django\core\handlers\exception.py", line 34, in inner
    response = get_response(request)
  File "D:\pyWorkSpace\kangni\venv\lib\site-packages\django\core\handlers\base.py", line 145, in _get_response
    response = self.process_exception_by_middleware(e, request)
  File "D:\pyWorkSpace\kangni\venv\lib\site-packages\django\core\handlers\base.py", line 143, in _get_response
    response = response.render()
  File "D:\pyWorkSpace\kangni\venv\lib\site-packages\django\template\response.py", line 106, in render
    self.content = self.rendered_content
  File "D:\pyWorkSpace\kangni\venv\lib\site-packages\django\template\response.py", line 83, in rendered_content
    content = template.render(context, self._request)
  File "D:\pyWorkSpace\kangni\venv\lib\site-packages\django\template\backends\django.py", line 61, in render
    return self.template.render(context)
  File "D:\pyWorkSpace\kangni\venv\lib\site-packages\django\template\base.py", line 171, in render
    return self._render(context)
  File "D:\pyWorkSpace\kangni\venv\lib\site-packages\django\template\base.py", line 163, in _render
    return self.nodelist.render(context)
  File "D:\pyWorkSpace\kangni\venv\lib\site-packages\django\template\base.py", line 937, in render
    bit = node.render_annotated(context)
  File "D:\pyWorkSpace\kangni\venv\lib\site-packages\django\template\base.py", line 904, in render_annotated
    return self.render(context)
  File "D:\pyWorkSpace\kangni\venv\lib\site-packages\django\template\loader_tags.py", line 150, in render
    return compiled_parent._render(context)
  File "D:\pyWorkSpace\kangni\venv\lib\site-packages\django\template\base.py", line 163, in _render
    return self.nodelist.render(context)
  File "D:\pyWorkSpace\kangni\venv\lib\site-packages\django\template\base.py", line 937, in render
    bit = node.render_annotated(context)
  File "D:\pyWorkSpace\kangni\venv\lib\site-packages\django\template\base.py", line 904, in render_annotated
    return self.render(context)
  File "D:\pyWorkSpace\kangni\venv\lib\site-packages\django\template\loader_tags.py", line 150, in render
    return compiled_parent._render(context)
  File "D:\pyWorkSpace\kangni\venv\lib\site-packages\django\template\base.py", line 163, in _render
    return self.nodelist.render(context)
  File "D:\pyWorkSpace\kangni\venv\lib\site-packages\django\template\base.py", line 937, in render
    bit = node.render_annotated(context)
  File "D:\pyWorkSpace\kangni\venv\lib\site-packages\django\template\base.py", line 904, in render_annotated
    return self.render(context)
  File "D:\pyWorkSpace\kangni\venv\lib\site-packages\django\template\loader_tags.py", line 150, in render
    return compiled_parent._render(context)
  File "D:\pyWorkSpace\kangni\venv\lib\site-packages\django\template\base.py", line 163, in _render
    return self.nodelist.render(context)
  File "D:\pyWorkSpace\kangni\venv\lib\site-packages\django\template\base.py", line 937, in render
    bit = node.render_annotated(context)
  File "D:\pyWorkSpace\kangni\venv\lib\site-packages\django\template\base.py", line 904, in render_annotated
    return self.render(context)
  File "D:\pyWorkSpace\kangni\venv\lib\site-packages\django\template\loader_tags.py", line 150, in render
    return compiled_parent._render(context)
  File "D:\pyWorkSpace\kangni\venv\lib\site-packages\django\template\base.py", line 163, in _render
    return self.nodelist.render(context)
  File "D:\pyWorkSpace\kangni\venv\lib\site-packages\django\template\base.py", line 937, in render
    bit = node.render_annotated(context)
  File "D:\pyWorkSpace\kangni\venv\lib\site-packages\django\template\base.py", line 904, in render_annotated
    return self.render(context)
  File "D:\pyWorkSpace\kangni\venv\lib\site-packages\django\template\defaulttags.py", line 309, in render
    return nodelist.render(context)
  File "D:\pyWorkSpace\kangni\venv\lib\site-packages\django\template\base.py", line 937, in render
    bit = node.render_annotated(context)
  File "D:\pyWorkSpace\kangni\venv\lib\site-packages\django\template\base.py", line 904, in render_annotated
    return self.render(context)
  File "D:\pyWorkSpace\kangni\venv\lib\site-packages\django\template\loader_tags.py", line 62, in render
    result = block.nodelist.render(context)
  File "D:\pyWorkSpace\kangni\venv\lib\site-packages\django\template\base.py", line 937, in render
    bit = node.render_annotated(context)
  File "D:\pyWorkSpace\kangni\venv\lib\site-packages\django\template\base.py", line 904, in render_annotated
    return self.render(context)
  File "D:\pyWorkSpace\kangni\venv\lib\site-packages\django\template\loader_tags.py", line 62, in render
    result = block.nodelist.render(context)
  File "D:\pyWorkSpace\kangni\venv\lib\site-packages\django\template\base.py", line 937, in render
    bit = node.render_annotated(context)
  File "D:\pyWorkSpace\kangni\venv\lib\site-packages\django\template\base.py", line 904, in render_annotated
    return self.render(context)
  File "D:\pyWorkSpace\kangni\venv\lib\site-packages\django\contrib\admin\templatetags\base.py", line 33, in render
    return super().render(context)
  File "D:\pyWorkSpace\kangni\venv\lib\site-packages\django\template\library.py", line 214, in render
    _dict = self.func(*resolved_args, **resolved_kwargs)
  File "D:\pyWorkSpace\kangni\venv\lib\site-packages\django\contrib\admin\templatetags\admin_list.py", line 339, in result_list
    'results': list(results(cl)),
  File "D:\pyWorkSpace\kangni\venv\lib\site-packages\django\contrib\admin\templatetags\admin_list.py", line 312, in results
    yield ResultList(form, items_for_result(cl, res, form))
  File "D:\pyWorkSpace\kangni\venv\lib\site-packages\django\contrib\admin\templatetags\admin_list.py", line 306, in __init__
    super().__init__(*items)
  File "D:\pyWorkSpace\kangni\venv\lib\site-packages\django\contrib\admin\templatetags\admin_list.py", line 229, in items_for_result
    f, attr, value = lookup_field(field_name, result, cl.model_admin)
  File "D:\pyWorkSpace\kangni\venv\lib\site-packages\django\contrib\admin\utils.py", line 271, in lookup_field
    value = attr(obj)
  File "D:\pyWorkSpace\kangni\resource\admin.py", line 169, in district
    return obj.position.district.name
AttributeError: 'NoneType' object has no attribute 'district'
