[INFO][2019-08-06 22:30:41,170][autoreload.py:584]Watching for file changes with StatReloader
[INFO][2019-08-06 22:31:21,366][views.py:69]添加事件成功，图片路径：D:\github_workspace\kangni\media\events\2019-08-06\20190806223121891815.png
[INFO][2019-08-06 22:31:59,510][views.py:69]添加事件成功，图片路径：D:\github_workspace\kangni\media\events\2019-08-06\20190806223159886018.png
[INFO][2019-08-06 22:33:35,293][views.py:69]添加事件成功，图片路径：D:\github_workspace\kangni\media\events\2019-08-06\20190806223335208052.png
[INFO][2019-08-06 22:34:53,852][views.py:69]添加事件成功，图片路径：D:\github_workspace\kangni\media\events\2019-08-06\20190806223453077498.png
[INFO][2019-08-06 22:35:32,005][views.py:69]添加事件成功，图片路径：D:\github_workspace\kangni\media\events\2019-08-06\20190806223531899448.png
[INFO][2019-08-06 22:44:19,325][autoreload.py:584]Watching for file changes with StatReloader
[INFO][2019-08-06 22:45:05,549][autoreload.py:211]D:\github_workspace\kangni\resource\admin.py changed, reloading.
[INFO][2019-08-06 22:45:08,883][autoreload.py:584]Watching for file changes with StatReloader
[INFO][2019-08-06 22:45:33,176][autoreload.py:584]Watching for file changes with StatReloader
[ERROR][2019-08-06 22:46:00,206][log.py:228]Internal Server Error: /log/
Traceback (most recent call last):
  File "D:\Program Files\Python36\lib\site-packages\django\db\backends\utils.py", line 82, in _execute
    return self.cursor.execute(sql)
  File "D:\Program Files\Python36\lib\site-packages\django\db\backends\mysql\base.py", line 71, in execute
    return self.cursor.execute(query, args)
  File "D:\Program Files\Python36\lib\site-packages\MySQLdb\cursors.py", line 206, in execute
    res = self._query(query)
  File "D:\Program Files\Python36\lib\site-packages\MySQLdb\cursors.py", line 312, in _query
    db.query(q)
  File "D:\Program Files\Python36\lib\site-packages\MySQLdb\connections.py", line 224, in query
    _mysql.connection.query(self, query)
MySQLdb._exceptions.OperationalError: (1054, "Unknown column 'rev.employe_id' in 'on clause'")

The above exception was the direct cause of the following exception:

Traceback (most recent call last):
  File "D:\Program Files\Python36\lib\site-packages\django\core\handlers\exception.py", line 34, in inner
    response = get_response(request)
  File "D:\Program Files\Python36\lib\site-packages\django\core\handlers\base.py", line 115, in _get_response
    response = self.process_exception_by_middleware(e, request)
  File "D:\Program Files\Python36\lib\site-packages\django\core\handlers\base.py", line 113, in _get_response
    response = wrapped_callback(request, *callback_args, **callback_kwargs)
  File "D:\github_workspace\kangni\log\views.py", line 12, in index
    context = {"bar": bar(), "geo": geo(), "pie_base": pie_base(), "gauge_base": gauge_base()}
  File "D:\github_workspace\kangni\log\views.py", line 78, in bar
    GROUP BY employe_id,event_type_id;""")
  File "D:\Program Files\Python36\lib\site-packages\django\db\backends\utils.py", line 99, in execute
    return super().execute(sql, params)
  File "D:\Program Files\Python36\lib\site-packages\django\db\backends\utils.py", line 67, in execute
    return self._execute_with_wrappers(sql, params, many=False, executor=self._execute)
  File "D:\Program Files\Python36\lib\site-packages\django\db\backends\utils.py", line 76, in _execute_with_wrappers
    return executor(sql, params, many, context)
  File "D:\Program Files\Python36\lib\site-packages\django\db\backends\utils.py", line 84, in _execute
    return self.cursor.execute(sql, params)
  File "D:\Program Files\Python36\lib\site-packages\django\db\utils.py", line 89, in __exit__
    raise dj_exc_value.with_traceback(traceback) from exc_value
  File "D:\Program Files\Python36\lib\site-packages\django\db\backends\utils.py", line 82, in _execute
    return self.cursor.execute(sql)
  File "D:\Program Files\Python36\lib\site-packages\django\db\backends\mysql\base.py", line 71, in execute
    return self.cursor.execute(query, args)
  File "D:\Program Files\Python36\lib\site-packages\MySQLdb\cursors.py", line 206, in execute
    res = self._query(query)
  File "D:\Program Files\Python36\lib\site-packages\MySQLdb\cursors.py", line 312, in _query
    db.query(q)
  File "D:\Program Files\Python36\lib\site-packages\MySQLdb\connections.py", line 224, in query
    _mysql.connection.query(self, query)
django.db.utils.OperationalError: (1054, "Unknown column 'rev.employe_id' in 'on clause'")
[INFO][2019-08-06 22:47:35,476][autoreload.py:584]Watching for file changes with StatReloader
[INFO][2019-08-06 23:44:05,343][autoreload.py:584]Watching for file changes with StatReloader
[WARNING][2019-08-06 23:44:20,329][log.py:228]Not Found: /favicon.ico
[ERROR][2019-08-06 23:44:38,544][log.py:228]Internal Server Error: /log/
Traceback (most recent call last):
  File "D:\pyWorkSpace\kangni\venv\lib\site-packages\django\db\backends\utils.py", line 82, in _execute
    return self.cursor.execute(sql)
  File "D:\pyWorkSpace\kangni\venv\lib\site-packages\django\db\backends\mysql\base.py", line 71, in execute
    return self.cursor.execute(query, args)
  File "D:\pyWorkSpace\kangni\venv\lib\site-packages\MySQLdb\cursors.py", line 206, in execute
    res = self._query(query)
  File "D:\pyWorkSpace\kangni\venv\lib\site-packages\MySQLdb\cursors.py", line 312, in _query
    db.query(q)
  File "D:\pyWorkSpace\kangni\venv\lib\site-packages\MySQLdb\connections.py", line 224, in query
    _mysql.connection.query(self, query)
MySQLdb._exceptions.OperationalError: (1054, "Unknown column 'rev.employe_id' in 'on clause'")

The above exception was the direct cause of the following exception:

Traceback (most recent call last):
  File "D:\pyWorkSpace\kangni\venv\lib\site-packages\django\core\handlers\exception.py", line 34, in inner
    response = get_response(request)
  File "D:\pyWorkSpace\kangni\venv\lib\site-packages\django\core\handlers\base.py", line 115, in _get_response
    response = self.process_exception_by_middleware(e, request)
  File "D:\pyWorkSpace\kangni\venv\lib\site-packages\django\core\handlers\base.py", line 113, in _get_response
    response = wrapped_callback(request, *callback_args, **callback_kwargs)
  File "D:\pyWorkSpace\kangni\log\views.py", line 12, in index
    context = {"bar": bar(), "geo": geo(), "pie_base": pie_base(), "gauge_base": gauge_base()}
  File "D:\pyWorkSpace\kangni\log\views.py", line 78, in bar
    GROUP BY employe_id,event_type_id;""")
  File "D:\pyWorkSpace\kangni\venv\lib\site-packages\django\db\backends\utils.py", line 99, in execute
    return super().execute(sql, params)
  File "D:\pyWorkSpace\kangni\venv\lib\site-packages\django\db\backends\utils.py", line 67, in execute
    return self._execute_with_wrappers(sql, params, many=False, executor=self._execute)
  File "D:\pyWorkSpace\kangni\venv\lib\site-packages\django\db\backends\utils.py", line 76, in _execute_with_wrappers
    return executor(sql, params, many, context)
  File "D:\pyWorkSpace\kangni\venv\lib\site-packages\django\db\backends\utils.py", line 84, in _execute
    return self.cursor.execute(sql, params)
  File "D:\pyWorkSpace\kangni\venv\lib\site-packages\django\db\utils.py", line 89, in __exit__
    raise dj_exc_value.with_traceback(traceback) from exc_value
  File "D:\pyWorkSpace\kangni\venv\lib\site-packages\django\db\backends\utils.py", line 82, in _execute
    return self.cursor.execute(sql)
  File "D:\pyWorkSpace\kangni\venv\lib\site-packages\django\db\backends\mysql\base.py", line 71, in execute
    return self.cursor.execute(query, args)
  File "D:\pyWorkSpace\kangni\venv\lib\site-packages\MySQLdb\cursors.py", line 206, in execute
    res = self._query(query)
  File "D:\pyWorkSpace\kangni\venv\lib\site-packages\MySQLdb\cursors.py", line 312, in _query
    db.query(q)
  File "D:\pyWorkSpace\kangni\venv\lib\site-packages\MySQLdb\connections.py", line 224, in query
    _mysql.connection.query(self, query)
django.db.utils.OperationalError: (1054, "Unknown column 'rev.employe_id' in 'on clause'")
[INFO][2019-08-06 23:56:44,341][autoreload.py:584]Watching for file changes with StatReloader
[WARNING][2019-08-07 00:02:32,334][log.py:228]Forbidden (CSRF cookie not set.): /resource/addEvent
[INFO][2019-08-07 00:03:04,836][autoreload.py:211]D:\pyWorkSpace\kangni\kangni\settings.py changed, reloading.
[INFO][2019-08-07 00:03:09,050][autoreload.py:584]Watching for file changes with StatReloader
[INFO][2019-08-07 00:04:42,027][autoreload.py:584]Watching for file changes with StatReloader
[INFO][2019-08-07 00:06:24,591][autoreload.py:584]Watching for file changes with StatReloader
[INFO][2019-08-07 00:06:31,559][views.py:80]添加事件成功，图片路径：D:\pyWorkSpace\kangni\media\events\2019-08-07\20190807000631540748.png
[ERROR][2019-08-07 00:07:34,603][views.py:57]摄像头不存在！
[INFO][2019-08-07 00:17:00,610][autoreload.py:211]D:\pyWorkSpace\kangni\log\views.py changed, reloading.
[INFO][2019-08-07 00:17:06,073][autoreload.py:584]Watching for file changes with StatReloader
[INFO][2019-08-07 00:23:50,052][autoreload.py:584]Watching for file changes with StatReloader
[ERROR][2019-08-07 00:24:03,933][log.py:228]Internal Server Error: /log/
Traceback (most recent call last):
  File "D:\pyWorkSpace\kangni\venv\lib\site-packages\django\core\handlers\exception.py", line 34, in inner
    response = get_response(request)
  File "D:\pyWorkSpace\kangni\venv\lib\site-packages\django\core\handlers\base.py", line 115, in _get_response
    response = self.process_exception_by_middleware(e, request)
  File "D:\pyWorkSpace\kangni\venv\lib\site-packages\django\core\handlers\base.py", line 113, in _get_response
    response = wrapped_callback(request, *callback_args, **callback_kwargs)
  File "D:\pyWorkSpace\kangni\log\views.py", line 13, in index
    context = {"bar": bar(), "geo": geo(), "pie_base": pie_base(), "gauge_base": gauge_base()}
  File "D:\pyWorkSpace\kangni\log\views.py", line 117, in pie_base
    .add("", ['人脸识别','未系安全带','未戴安全帽','跨越围栏'], [4,9,5,1])
TypeError: add() takes 3 positional arguments but 4 were given
[INFO][2019-08-07 00:26:13,804][autoreload.py:211]D:\pyWorkSpace\kangni\log\views.py changed, reloading.
[INFO][2019-08-07 00:26:19,362][autoreload.py:584]Watching for file changes with StatReloader
[INFO][2019-08-07 00:27:16,268][autoreload.py:211]D:\pyWorkSpace\kangni\log\views.py changed, reloading.
[INFO][2019-08-07 00:27:21,874][autoreload.py:584]Watching for file changes with StatReloader
[INFO][2019-08-07 00:27:56,506][autoreload.py:584]Watching for file changes with StatReloader
[INFO][2019-08-07 00:32:16,326][autoreload.py:584]Watching for file changes with StatReloader
[INFO][2019-08-07 00:33:52,159][autoreload.py:584]Watching for file changes with StatReloader
[INFO][2019-08-07 00:43:21,685][autoreload.py:211]D:\pyWorkSpace\kangni\log\views.py changed, reloading.
[INFO][2019-08-07 00:43:27,746][autoreload.py:584]Watching for file changes with StatReloader
[INFO][2019-08-07 00:44:33,653][autoreload.py:211]D:\pyWorkSpace\kangni\log\views.py changed, reloading.
[INFO][2019-08-07 00:44:38,281][autoreload.py:584]Watching for file changes with StatReloader
[INFO][2019-08-07 00:46:05,150][autoreload.py:211]D:\pyWorkSpace\kangni\log\views.py changed, reloading.
[INFO][2019-08-07 00:46:10,372][autoreload.py:584]Watching for file changes with StatReloader
[INFO][2019-08-07 00:46:44,134][autoreload.py:584]Watching for file changes with StatReloader
[ERROR][2019-08-07 00:46:51,592][log.py:228]Internal Server Error: /log/
Traceback (most recent call last):
  File "D:\pyWorkSpace\kangni\venv\lib\site-packages\django\core\handlers\exception.py", line 34, in inner
    response = get_response(request)
  File "D:\pyWorkSpace\kangni\venv\lib\site-packages\django\core\handlers\base.py", line 115, in _get_response
    response = self.process_exception_by_middleware(e, request)
  File "D:\pyWorkSpace\kangni\venv\lib\site-packages\django\core\handlers\base.py", line 113, in _get_response
    response = wrapped_callback(request, *callback_args, **callback_kwargs)
  File "D:\pyWorkSpace\kangni\log\views.py", line 13, in index
    context = {"bar": bar(), "line": line(), "pie_base": pie_base(), "gauge_base": gauge_base()}
  File "D:\pyWorkSpace\kangni\log\views.py", line 103, in bar
    tmp_list[index] = row[2]
IndexError: tuple index out of range
[INFO][2019-08-07 00:48:55,178][autoreload.py:584]Watching for file changes with StatReloader
[INFO][2019-08-07 00:49:58,014][autoreload.py:584]Watching for file changes with StatReloader
[INFO][2019-08-07 00:52:25,375][autoreload.py:584]Watching for file changes with StatReloader
[INFO][2019-08-07 00:53:56,973][autoreload.py:584]Watching for file changes with StatReloader
[INFO][2019-08-07 00:54:51,713][autoreload.py:211]D:\pyWorkSpace\kangni\log\views.py changed, reloading.
[INFO][2019-08-07 00:55:05,437][autoreload.py:584]Watching for file changes with StatReloader
[INFO][2019-08-07 00:56:47,426][autoreload.py:584]Watching for file changes with StatReloader
[INFO][2019-08-07 00:59:57,119][autoreload.py:584]Watching for file changes with StatReloader
[INFO][2019-08-07 01:05:33,748][autoreload.py:211]D:\pyWorkSpace\kangni\log\views.py changed, reloading.
[INFO][2019-08-07 01:05:39,061][autoreload.py:584]Watching for file changes with StatReloader
[INFO][2019-08-07 01:06:47,563][autoreload.py:211]D:\pyWorkSpace\kangni\log\views.py changed, reloading.
[INFO][2019-08-07 01:06:52,219][autoreload.py:584]Watching for file changes with StatReloader
[INFO][2019-08-07 01:08:46,664][autoreload.py:211]D:\pyWorkSpace\kangni\log\views.py changed, reloading.
[INFO][2019-08-07 01:08:53,126][autoreload.py:584]Watching for file changes with StatReloader
[INFO][2019-08-07 01:11:33,093][autoreload.py:211]D:\pyWorkSpace\kangni\log\views.py changed, reloading.
[INFO][2019-08-07 01:11:39,309][autoreload.py:584]Watching for file changes with StatReloader
[INFO][2019-08-07 01:12:41,089][autoreload.py:584]Watching for file changes with StatReloader
[INFO][2019-08-07 01:13:41,540][autoreload.py:211]D:\pyWorkSpace\kangni\log\views.py changed, reloading.
[INFO][2019-08-07 01:13:46,415][autoreload.py:584]Watching for file changes with StatReloader
[INFO][2019-08-07 01:15:24,705][autoreload.py:211]D:\pyWorkSpace\kangni\log\views.py changed, reloading.
[INFO][2019-08-07 01:15:29,543][autoreload.py:584]Watching for file changes with StatReloader
[INFO][2019-08-07 01:16:19,667][autoreload.py:211]D:\pyWorkSpace\kangni\log\views.py changed, reloading.
[INFO][2019-08-07 01:16:25,230][autoreload.py:584]Watching for file changes with StatReloader
[INFO][2019-08-07 01:16:53,083][autoreload.py:211]D:\pyWorkSpace\kangni\log\views.py changed, reloading.
[INFO][2019-08-07 01:16:58,506][autoreload.py:584]Watching for file changes with StatReloader
[INFO][2019-08-07 01:18:42,229][autoreload.py:584]Watching for file changes with StatReloader
[INFO][2019-08-07 01:22:01,167][autoreload.py:584]Watching for file changes with StatReloader
[INFO][2019-08-07 01:23:44,190][autoreload.py:584]Watching for file changes with StatReloader
[INFO][2019-08-07 10:26:54,652][autoreload.py:584]Watching for file changes with StatReloader
[WARNING][2019-08-07 10:27:18,415][log.py:228]Not Found: /favicon.ico
[INFO][2019-08-07 10:32:37,098][autoreload.py:211]D:\pyWorkSpace\kangni\log\views.py changed, reloading.
[INFO][2019-08-07 10:32:42,239][autoreload.py:584]Watching for file changes with StatReloader
[INFO][2019-08-07 10:34:57,940][autoreload.py:584]Watching for file changes with StatReloader
[INFO][2019-08-07 10:40:19,134][autoreload.py:584]Watching for file changes with StatReloader
[INFO][2019-08-07 10:43:34,887][autoreload.py:584]Watching for file changes with StatReloader
[INFO][2019-08-07 10:47:46,067][autoreload.py:584]Watching for file changes with StatReloader
[INFO][2019-08-07 10:51:06,761][autoreload.py:584]Watching for file changes with StatReloader
[INFO][2019-08-07 10:52:05,871][autoreload.py:584]Watching for file changes with StatReloader
[INFO][2019-08-07 10:52:55,542][autoreload.py:211]D:\pyWorkSpace\kangni\log\views.py changed, reloading.
[INFO][2019-08-07 10:53:02,244][autoreload.py:584]Watching for file changes with StatReloader
[INFO][2019-08-07 11:01:49,398][autoreload.py:584]Watching for file changes with StatReloader
[INFO][2019-08-07 11:03:12,866][autoreload.py:584]Watching for file changes with StatReloader
[INFO][2019-08-07 11:03:54,233][autoreload.py:584]Watching for file changes with StatReloader
[INFO][2019-08-07 11:06:06,658][autoreload.py:584]Watching for file changes with StatReloader
[INFO][2019-08-07 11:07:42,460][autoreload.py:584]Watching for file changes with StatReloader
[INFO][2019-08-07 11:10:51,699][autoreload.py:211]D:\pyWorkSpace\kangni\log\views.py changed, reloading.
[INFO][2019-08-07 11:10:58,146][autoreload.py:584]Watching for file changes with StatReloader
[INFO][2019-08-07 11:12:20,768][autoreload.py:584]Watching for file changes with StatReloader
[INFO][2019-08-07 11:14:48,268][autoreload.py:584]Watching for file changes with StatReloader
[INFO][2019-08-07 11:17:23,127][autoreload.py:584]Watching for file changes with StatReloader
[INFO][2019-08-07 11:18:16,966][autoreload.py:584]Watching for file changes with StatReloader
[INFO][2019-08-07 11:27:17,759][autoreload.py:584]Watching for file changes with StatReloader
[ERROR][2019-08-07 11:27:24,837][log.py:228]Internal Server Error: /log/
Traceback (most recent call last):
  File "D:\pyWorkSpace\kangni\venv\lib\site-packages\django\core\handlers\exception.py", line 34, in inner
    response = get_response(request)
  File "D:\pyWorkSpace\kangni\venv\lib\site-packages\django\core\handlers\base.py", line 115, in _get_response
    response = self.process_exception_by_middleware(e, request)
  File "D:\pyWorkSpace\kangni\venv\lib\site-packages\django\core\handlers\base.py", line 113, in _get_response
    response = wrapped_callback(request, *callback_args, **callback_kwargs)
  File "D:\pyWorkSpace\kangni\log\views.py", line 13, in index
    context = {"bar": bar(), "line": line(), "pie_base": pie_base(), "timeline_bar": timeline_bar()}
  File "D:\pyWorkSpace\kangni\log\views.py", line 211, in timeline_bar
    num = row[3]
IndexError: tuple index out of range
[ERROR][2019-08-07 11:28:01,977][log.py:228]Internal Server Error: /log/
Traceback (most recent call last):
  File "D:\pyWorkSpace\kangni\venv\lib\site-packages\django\core\handlers\exception.py", line 34, in inner
    response = get_response(request)
  File "D:\pyWorkSpace\kangni\venv\lib\site-packages\django\core\handlers\base.py", line 115, in _get_response
    response = self.process_exception_by_middleware(e, request)
  File "D:\pyWorkSpace\kangni\venv\lib\site-packages\django\core\handlers\base.py", line 113, in _get_response
    response = wrapped_callback(request, *callback_args, **callback_kwargs)
  File "D:\pyWorkSpace\kangni\log\views.py", line 13, in index
    context = {"bar": bar(), "line": line(), "pie_base": pie_base(), "timeline_bar": timeline_bar()}
  File "D:\pyWorkSpace\kangni\log\views.py", line 211, in timeline_bar
    num = row[3]
IndexError: tuple index out of range
[INFO][2019-08-07 11:28:28,681][autoreload.py:584]Watching for file changes with StatReloader
[INFO][2019-08-07 11:29:23,078][autoreload.py:211]D:\pyWorkSpace\kangni\log\views.py changed, reloading.
[INFO][2019-08-07 11:29:29,343][autoreload.py:584]Watching for file changes with StatReloader
[INFO][2019-08-07 11:30:00,257][autoreload.py:584]Watching for file changes with StatReloader
[INFO][2019-08-07 11:35:37,840][autoreload.py:584]Watching for file changes with StatReloader
